Workbook

Sheet employee_data
A1: EmpID | B1: Full Name | C1: StartDate | D1: ExitDate | E1: Title | F1: Supervisor | G1: ADEmail | H1: BusinessUnit | I1: EmployeeStatus | J1: EmployeeType | K1: PayZone | L1: EmployeeClassificationType | M1: TerminationType | N1: TerminationDescription | O1: DepartmentType | P1: Division | Q1: DOB | R1: State | S1: JobFunctionDescription | T1: GenderCode | U1: LocationCode | V1: RaceDesc | W1: MaritalDesc | X1: Performance Score | Y1: Current Employee Rating
A2: 1001 | B2: Susan Exantus | C2: 43706 | D2: N/A | E2: Software Engineer | F2: Angela Carlson | G2: susan.exantus@bilearner.com | H2: BPC | I2: Active | J2: Part-Time | K2: Zone A | L2: Part-Time | M2: Unk | N2: N/A | O2: Software Engineering | P2: Engineers | Q2: 21084 | R2: MA | S2: Engineer | T2: Female | U2: 1749 | V2: Black | W2: Married | X2: Fully Meets | Y2: 3 | AB2: EMPLOYE STATUS COUNT | AD2: Percentage Calculation
A3: 1002 | B3: Sandra Martin | C3: 44907 | D3: 45074 | E3: Software Engineer | F3: Angela Hayes | G3: sandra.martin@bilearner.com | H3: NEL | I3: Terminated for Cause | J3: Part-Time | K3: Zone A | L3: Temporary | M3: Involuntary | N3: Behind buy our of very claim. | O3: Software Engineering | P3: Catv | Q3: 18452 | R3: MA | S3: Foreman | T3: Female | U3: 2135 | V3: Asian | W3: Widowed | X3: Fully Meets | Y3: 3 | AB3: Total Headcount | AC3: =COUNTA(Table4[EmpID]) -> 3000
A4: 1003 | B4: Keyla Del Bosque | C4: 44993 | D4: 45000 | E4: Software Engineer | F4: Christina Copeland | G4: keyla.delbosque@bilearner.com | H4: WBL | I4: Voluntarily Terminated | J4: Contract | K4: Zone A | L4: Part-Time | M4: Voluntary | N4: Some make teach quite range seem conference. | O4: Software Engineering | P4: Field Operations | Q4: 26991 | R4: MA | S4: Foreman | T4: Female | U4: 2176 | V4: White | W4: Married | X4: Fully Meets | Y4: 3 | AB4: Active Count | AC4: =COUNTIF(Table4[EmployeeStatus],"Active") -> 1661 | AD4: =AC4/AC3 -> 0.55366667
A5: 1004 | B5: Andrew Szabo | C5: 43980 | D5: 44260 | E5: Software Engineer | F5: Jennifer Cohen | G5: andrew.szabo@bilearner.com | H5: PYZ | I5: Terminated for Cause | J5: Part-Time | K5: Zone C | L5: Part-Time | M5: Involuntary | N5: Enter beautiful social store. | O5: Software Engineering | P5: Project Management - Con | Q5: 20847 | R5: MA | S5: Coordinator | T5: Male | U5: 2140 | V5: Black | W5: Single | X5: Fully Meets | Y5: 3 | AB5: Voluntarily Terminated Count | AC5: =COUNTIF(Table4[EmployeeStatus],"Voluntarily Terminated") -> 935 | AD5: =AC5/AC3 -> 0.31166667
A6: 1005 | B6: Luke Patronick | C6: 44820 | D6: N/A | E6: Software Engineer | F6: Mr. Jesus Richards | G6: colby.andreola@bilearner.com | H6: SVG | I6: Voluntarily Terminated | J6: Full-Time | K6: Zone B | L6: S | M6: Unk | N6: N/A | O6: Software Engineering | P6: Field Operations | Q6: 25777 | R6: MA | S6: Project Manager | T6: Male | U6: 1844 | V6: Black | W6: Divorced | X6: Fully Meets | Y6: 3 | AB6: Terminated for Cause Count | AC6: =COUNTIF(Table4[EmployeeStatus],"Terminated for Cause") -> 272 | AD6: =AC6/AC3 -> 0.090666667
A7: 1006 | B7: Colby Andreola | C7: 44423 | D7: 44520 | E7: Software Engineer | F7: Beth Johnson | G7: edward.true@bilearner.com | H7: MSC | I7: Voluntarily Terminated | J7: Full-Time | K7: Zone C | L7: Part-Time | M7: Resignation | N7: Throughout yet in serious here wish. | O7: Software Engineering | P7: Engineers | Q7: 21600 | R7: MA | S7: Administrative | T7: Female | U7: 2110 | V7: White | W7: Widowed | X7: Fully Meets | Y7: 3 | AB7: Leave of Absence | AC7: =COUNTIF(Table4[EmployeeStatus],"Leave of Absence") -> 74 | AD7: =AC7/AC3 -> 0.024666667
A8: 1007 | B8: Edward TRUE | C8: 44129 | D8: 44465 | E8: Software Engineer | F8: Raymond Adams | G8: judith.carabbio@bilearner.com | H8: SVG | I8: Voluntarily Terminated | J8: Part-Time | K8: Zone A | L8: Part-Time | M8: Involuntary | N8: Recently however meeting economic. | O8: Software Engineering | P8: General - Con | Q8: 36603 | R8: MA | S8: Lineman | T8: Male | U8: 2451 | V8: Black | W8: Widowed | X8: Fully Meets | Y8: 3 | AB8: Future Start | AC8: =COUNTIF(Table4[EmployeeStatus],"Future Start") -> 58 | AD8: =AC8/AC3 -> 0.019333333
A9: 1008 | B9: Judith Carabbio | C9: 43705 | D9: 43955 | E9: Software Engineer | F9: Jessica Rhodes | G9: adell.saada@bilearner.com | H9: BPC | I9: Voluntarily Terminated | J9: Contract | K9: Zone B | L9: Temporary | M9: Voluntary | N9: Instead story skill financial who. | O9: Software Engineering | P9: General - Con | Q9: 29941 | R9: MA | S9: Foreman | T9: Female | U9: 2132 | V9: Hispanic | W9: Married | X9: Fully Meets | Y9: 3
A10: 1009 | B10: Adell Saada | C10: 43629 | D10: 44938 | E10: Software Engineer | F10: Steven Tran | G10: kamari.hunter@bilearner.com | H10: NEL | I10: Terminated for Cause | J10: Part-Time | K10: Zone C | L10: Temporary | M10: Retirement | N10: Exactly vote including easy. | O10: Software Engineering | P10: General - Con | Q10: 31837 | R10: MA | S10: Model Assistant | T10: Female | U10: 2132 | V10: Other | W10: Single | X10: Fully Meets | Y10: 3
A11: 1010 | B11: Kamari Hunter | C11: 44208 | D11: 44638 | E11: Software Engineer | F11: Kristen Collier | G11: sarah.malone@bilearner.com | H11: EW | I11: Terminated for Cause | J11: Part-Time | K11: Zone C | L11: Temporary | M11: Voluntary | N11: West note present Mr woman family. | O11: Software Engineering | P11: Field Operations | Q11: 33898 | R11: MA | S11: Supervisor | T11: Male | U11: 12889 | V11: Hispanic | W11: Divorced | X11: Fully Meets | Y11: 3
A12: 1011 | B12: Sarah Malone | C12: 44599 | D12: 44969 | E12: Software Engineer | F12: David Lopez | G12: skyler.blackwell@bilearner.com | H12: MSC | I12: Terminated for Cause | J12: Contract | K12: Zone A | L12: Temporary | M12: Resignation | N12: Professor situation they bag interest there. | O12: Software Engineering | P12: General - Con | Q12: 17585 | R12: MA | S12: Foreman | T12: Male | U12: 21340 | V12: Hispanic | W12: Married | X12: Fully Meets | Y12: 3
A13: 1012 | B13: Skyler Blackwell | C13: 44144 | D13: 44353 | E13: Software Engineer | F13: Candice Schmidt | G13: kole.quinn@bilearner.com | H13: TNS | I13: Voluntarily Terminated | J13: Contract | K13: Zone A | L13: Temporary | M13: Involuntary | N13: Get apply economy artist right benefit ground. | O13: Software Engineering | P13: General - Eng | Q13: 28766 | R13: MA | S13: Administrative | T13: Male | U13: 67544 | V13: White | W13: Single | X13: Fully Meets | Y13: 3
A14: 1013 | B14: Jasmin Shah | C14: 43964 | D14: N/A | E14: Software Engineer | F14: Christy Craig | G14: jayda.reese@bilearner.com | H14: PYZ | I14: Terminated for Cause | J14: Part-Time | K14: Zone B | L14: Full-Time | M14: Unk | N14: N/A | O14: Software Engineering | P14: Engineers | Q14: 27352 | R14: MA | S14: Engineer | T14: Male | U14: 36398 | V14: Asian | W14: Single | X14: Fully Meets | Y14: 3
A15: 1014 | B15: Kole Quinn | C15: 44926 | D15: 45120 | E15: Shared Services Manager | F15: Jermaine Weaver | G15: julien.whitehead@bilearner.com | H15: WBL | I15: Voluntarily Terminated | J15: Part-Time | K15: Zone A | L15: Full-Time | M15: Retirement | N15: I back place no three offer economic. | O15: Software Engineering | P15: Catv | Q15: 19553 | R15: MA | S15: Clerk | T15: Male | U15: 2562 | V15: Other | W15: Single | X15: Fully Meets | Y15: 3
A16: 1015 | B16: Ansley Jackson | C16: 43437 | D16: N/A | E16: Shared Services Manager | F16: James Barajas | G16: alan.haynes@bilearner.com | H16: NEL | I16: Voluntarily Terminated | J16: Contract | K16: Zone A | L16: Part-Time | M16: Unk | N16: N/A | O16: Software Engineering | P16: People Services | Q16: 22619 | R16: MA | S16: Vp | T16: Female | U16: 22621 | V16: White | W16: Married | X16: Fully Meets | Y16: 3
A17: 1016 | B17: Jayda Reese | C17: 43882 | D17: 44345 | E17: Senior BI Developer | F17: Tyler Davis | G17: kamryn.herrera@bilearner.com | H17: PL | I17: Voluntarily Terminated | J17: Part-Time | K17: Zone B | L17: Part-Time | M17: Involuntary | N17: Friend agree stock teach price fish. | O17: Admin Offices | P17: Shop (Fleet) | Q17: 20522 | R17: MA | S17: Mechanic | T17: Female | U17: 64065 | V17: White | W17: Single | X17: Fully Meets | Y17: 3
A18: 1017 | B18: Julien Whitehead | C18: 44081 | D18: 44545 | E18: Senior BI Developer | F18: Joshua Gonzalez | G18: kelvin.foster@bilearner.com | H18: BPC | I18: Voluntarily Terminated | J18: Full-Time | K18: Zone B | L18: Full-Time | M18: Involuntary | N18: True system strong often experience. | O18: Admin Offices | P18: Field Operations | Q18: 17353 | R18: MA | S18: Laborer | T18: Female | U18: 97374 | V18: Black | W18: Single | X18: Fully Meets | Y18: 3
A19: 1018 | B19: Alan Haynes | C19: 44001 | D19: 44538 | E19: Senior BI Developer | F19: Justin Sherman | G19: joe.fletcher@bilearner.com | H19: CCDR | I19: Voluntarily Terminated | J19: Part-Time | K19: Zone A | L19: Part-Time | M19: Involuntary | N19: When price group admit fall fly around. | O19: Admin Offices | P19: General - Con | Q19: 15396 | R19: MA | S19: Laborer | T19: Female | U19: 87646 | V19: White | W19: Married | X19: Fully Meets | Y19: 3
A20: 1019 | B20: Kamryn Herrera | C20: 44848 | D20: 45135 | E20: Software Engineer | F20: Sara Holland | G20: nickolas.davila@bilearner.com | H20: EW | I20: Voluntarily Terminated | J20: Full-Time | K20: Zone A | L20: Temporary | M20: Retirement | N20: Article tough away forward home. Night author so. | O20: Software Engineering | P20: Fielders | Q20: 28822 | R20: MA | S20: Engineer | T20: Male | U20: 77974 | V20: Hispanic | W20: Widowed | X20: Fully Meets | Y20: 3
A21: 1020 | B21: Kelvin Foster | C21: 45097 | D21: 45125 | E21: Software Engineer | F21: Shelia Graham | G21: kasey.boyer@bilearner.com | H21: MSC | I21: Terminated for Cause | J21: Contract | K21: Zone C | L21: Full-Time | M21: Resignation | N21: Man issue never strategy will maintain resource. | O21: Software Engineering | P21: Field Operations | Q21: 33227 | R21: MA | S21: Supervisor | T21: Female | U21: 42126 | V21: Black | W21: Widowed | X21: Fully Meets | Y21: 3
A22: 1021 | B22: Joe Fletcher | C22: 44144 | D22: 45124 | E22: Software Engineer | F22: Amanda Hayden | G22: giovanni.jenkins@bilearner.com | H22: TNS | I22: Terminated for Cause | J22: Full-Time | K22: Zone C | L22: Full-Time | M22: Resignation | N22: Section hospital clearly season history. | O22: Software Engineering | P22: General - Eng | Q22: 32533 | R22: MA | S22: Billing | T22: Male | U22: 51613 | V22: Hispanic | W22: Single | X22: Fully Meets | Y22: 3
A23: 1022 | B23: Frederick Howe | C23: 44823 | D23: N/A | E23: Software Engineer | F23: Nicole Haynes | G23: alexis.moss@bilearner.com | H23: PYZ | I23: Voluntarily Terminated | J23: Part-Time | K23: Zone A | L23: Temporary | M23: Unk | N23: N/A | O23: Software Engineering | P23: Field Operations | Q23: 22808 | R23: MA | S23: Engineer | T23: Male | U23: 12765 | V23: Black | W23: Divorced | X23: Fully Meets | Y23: 3
A24: 1023 | B24: Nickolas Davila | C24: 43413 | D24: 44479 | E24: Shared Services Manager | F24: Debra Morales | G24: joanna.murphy@bilearner.com | H24: WBL | I24: Voluntarily Terminated | J24: Contract | K24: Zone C | L24: Part-Time | M24: Voluntary | N24: Each wish foot person morning per significant. | O24: Software Engineering | P24: General - Con | Q24: 33699 | R24: MA | S24: Clerk | T24: Male | U24: 64122 | V24: Hispanic | W24: Divorced | X24: Fully Meets | Y24: 3
A25: 1024 | B25: Kasey Boyer | C25: 43464 | D25: 44370 | E25: Shared Services Manager | F25: Chad Andrews | G25: joseph.schmidt@bilearner.com | H25: NEL | I25: Voluntarily Terminated | J25: Contract | K25: Zone A | L25: Part-Time | M25: Involuntary | N25: Free may every real agency as blue maintain. | O25: Software Engineering | P25: Fielders | Q25: 31866 | R25: MA | S25: Coordinator | T25: Female | U25: 91332 | V25: Other | W25: Divorced | X25: Fully Meets | Y25: 3
A26: 1025 | B26: Giovanni Jenkins | C26: 45057 | D26: 45061 | E26: Senior BI Developer | F26: John Wallace | G26: kiley.haynes@bilearner.com | H26: PL | I26: Voluntarily Terminated | J26: Full-Time | K26: Zone A | L26: Temporary | M26: Retirement | N26: Quite none ten order. | O26: Admin Offices | P26: Field Operations | Q26: 22233 | R26: MA | S26: Foreman | T26: Female | U26: 39827 | V26: Other | W26: Divorced | X26: Fully Meets | Y26: 3
A27: 1026 | B27: Alexis Moss | C27: 44868 | D27: 44966 | E27: Senior BI Developer | F27: Benjamin Frederick | G27: kody.jimenez@bilearner.com | H27: BPC | I27: Voluntarily Terminated | J27: Contract | K27: Zone A | L27: Part-Time | M27: Resignation | N27: Where forward evening huge cost share eat. | O27: Admin Offices | P27: Engineers | Q27: 18574 | R27: MA | S27: Engineer | T27: Female | U27: 27418 | V27: Other | W27: Widowed | X27: Fully Meets | Y27: 3
A28: 1027 | B28: Joanna Murphy | C28: 43996 | D28: 44345 | E28: Senior BI Developer | F28: Michael Ramos | G28: zoe.colon@bilearner.com | H28: CCDR | I28: Voluntarily Terminated | J28: Part-Time | K28: Zone A | L28: Full-Time | M28: Voluntary | N28: Open test message part risk. | O28: Admin Offices | P28: General - Con | Q28: 23001 | R28: MA | S28: Flagger | T28: Male | U28: 24931 | V28: Other | W28: Single | X28: Fully Meets | Y28: 3
A29: 1028 | B29: Joseph Schmidt | C29: 43753 | D29: 44927 | E29: Software Engineer | F29: Donna Boone | G29: nolan.perez@bilearner.com | H29: PYZ | I29: Voluntarily Terminated | J29: Full-Time | K29: Zone C | L29: Part-Time | M29: Resignation | N29: Federal less every character section think white. | O29: Software Engineering | P29: General - Con | Q29: 36821 | R29: MA | S29: Model Assistant | T29: Male | U29: 2121 | V29: Asian | W29: Single | X29: Fully Meets | Y29: 3
A30: 1029 | B30: Brittany Hurley | C30: 43949 | D30: N/A | E30: Software Engineer | F30: Jeffrey Johnston | G30: katrina.farrell@bilearner.com | H30: SVG | I30: Voluntarily Terminated | J30: Part-Time | K30: Zone B | L30: Part-Time | M30: Unk | N30: N/A | O30: Software Engineering | P30: Field Operations | Q30: 29007 | R30: MA | S30: Specialist | T30: Female | U30: 97697 | V30: Asian | W30: Divorced | X30: Fully Meets | Y30: 3
A31: 1030 | B31: Niko Hamilton | C31: 43767 | D31: N/A | E31: Software Engineer | F31: Sarah King | G31: camden.kelly@bilearner.com | H31: TNS | I31: Voluntarily Terminated | J31: Contract | K31: Zone C | L31: Temporary | M31: Unk | N31: N/A | O31: Software Engineering | P31: Field Operations | Q31: 20276 | R31: MA | S31: Foreman | T31: Male | U31: 75783 | V31: Black | W31: Single | X31: Fully Meets | Y31: 3
A32: 1031 | B32: Ruben Martinez | C32: 44314 | D32: N/A | E32: Software Engineer | F32: Cynthia Delgado | G32: kale.lang@bilearner.com | H32: WBL | I32: Voluntarily Terminated | J32: Part-Time | K32: Zone B | L32: Temporary | M32: Unk | N32: N/A | O32: Software Engineering | P32: General - Con | Q32: 26601 | R32: MA | S32: Lineman | T32: Male | U32: 26111 | V32: White | W32: Widowed | X32: Fully Meets | Y32: 3
A33: 1032 | B33: Kiley Haynes | C33: 44670 | D33: 44799 | E33: Software Engineer | F33: Dominique Bailey | G33: elliott.ashley@bilearner.com | H33: PYZ | I33: Voluntarily Terminated | J33: Full-Time | K33: Zone C | L33: Part-Time | M33: Voluntary | N33: Off part culture choose strong public. | O33: Software Engineering | P33: Aerial | Q33: 19906 | R33: MA | S33: Laborer | T33: Male | U33: 50656 | V33: Asian | W33: Widowed | X33: Fully Meets | Y33: 3
A34: 1033 | B34: Blaine Brooks | C34: 45013 | D34: N/A | E34: Shared Services Manager | F34: Teresa Meyer | G34: genesis.todd@bilearner.com | H34: WBL | I34: Voluntarily Terminated | J34: Contract | K34: Zone B | L34: Full-Time | M34: Unk | N34: N/A | O34: Software Engineering | P34: Field Operations | Q34: 35517 | R34: MA | S34: Operator | T34: Male | U34: 71808 | V34: Other | W34: Single | X34: Fully Meets | Y34: 3
A35: 1034 | B35: Dennis Livingston | C35: 43591 | D35: N/A | E35: Shared Services Manager | F35: Sarah Carey | G35: demarion.morrow@bilearner.com | H35: NEL | I35: Voluntarily Terminated | J35: Full-Time | K35: Zone C | L35: Part-Time | M35: Unk | N35: N/A | O35: Software Engineering | P35: Project Management - Con | Q35: 28467 | R35: MA | S35: Manager | T35: Female | U35: 1043 | V35: Black | W35: Single | X35: Fully Meets | Y35: 3
A36: 1035 | B36: Case Russell | C36: 44117 | D36: N/A | E36: Senior BI Developer | F36: Taylor Wright | G36: devon.hinton@bilearner.com | H36: PL | I36: Voluntarily Terminated | J36: Full-Time | K36: Zone A | L36: Temporary | M36: Unk | N36: N/A | O36: Admin Offices | P36: Underground | Q36: 28902 | R36: MA | S36: Laborer | T36: Female | U36: 41260 | V36: Asian | W36: Divorced | X36: Fully Meets | Y36: 3
A37: 1036 | B37: Kody Jimenez | C37: 44383 | D37: 44525 | E37: Senior BI Developer | F37: Daniel Moore | G37: jacquelyn.johns@bilearner.com | H37: BPC | I37: Terminated for Cause | J37: Part-Time | K37: Zone A | L37: Part-Time | M37: Resignation | N37: Teacher door money tend song. | O37: Admin Offices | P37: Field Operations | Q37: 34189 | R37: MA | S37: Foreman | T37: Male | U37: 15346 | V37: Asian | W37: Single | X37: Fully Meets | Y37: 3
A38: 1037 | B38: Zoe Colon | C38: 44098 | D38: 44137 | E38: Software Engineer | F38: Stacey Vargas | G38: blaine.keith@bilearner.com | H38: CCDR | I38: Terminated for Cause | J38: Part-Time | K38: Zone C | L38: Full-Time | M38: Voluntary | N38: Accept knowledge drop bar understand. | O38: Software Engineering | P38: Fielders | Q38: 34177 | R38: MA | S38: Engineer | T38: Male | U38: 4876 | V38: Other | W38: Widowed | X38: Fully Meets | Y38: 3
A39: 1038 | B39: Courtney Cowan | C39: 44944 | D39: N/A | E39: Software Engineer | F39: Beth Anderson | G39: frida.livingston@bilearner.com | H39: SVG | I39: Voluntarily Terminated | J39: Contract | K39: Zone B | L39: Part-Time | M39: Unk | N39: N/A | O39: Software Engineering | P39: Field Operations | Q39: 26057 | R39: MA | S39: Crew Leader | T39: Male | U39: 14886 | V39: Hispanic | W39: Married | X39: Fully Meets | Y39: 3
A40: 1039 | B40: Nolan Perez | C40: 43699 | D40: 44645 | E40: Software Engineer | F40: Joshua Daniels | G40: travis.vasquez@bilearner.com | H40: EW | I40: Terminated for Cause | J40: Part-Time | K40: Zone B | L40: Part-Time | M40: Involuntary | N40: Under follow guess lot minute able history face. | O40: Software Engineering | P40: Finance & Accounting | Q40: 30272 | R40: MA | S40: Administrative | T40: Female | U40: 46407 | V40: Other | W40: Widowed | X40: Fully Meets | Y40: 3
...

Sheet training_and_development
A1: Employee ID | B1: Training Date | C1: Training Program Name | D1: Training Type | E1: Training Outcome | F1: Location | G1: Trainer | H1: Training Duration(Days) | I1: Training Cost
A2: 1001 | B2: 44825 | C2: Customer Service | D2: Internal | E2: Failed | F2: Port Greg | G2: Amanda Daniels | H2: 4 | I2: 510.83
A3: 1002 | B3: 45126 | C3: Leadership Development | D3: Internal | E3: Failed | F3: Brandonview | G3: Brittany Chambers | H3: 2 | I3: 582.37
A4: 1003 | B4: 44981 | C4: Technical Skills | D4: Internal | E4: Failed | F4: Port Briannahaven | G4: Mark Roberson | H4: 4 | I4: 777.06
A5: 1004 | B5: 45261 | C5: Customer Service | D5: Internal | E5: Completed | F5: Knightborough | G5: Richard Fisher | H5: 2 | I5: 824.3
A6: 1005 | B6: 45265 | C6: Communication Skills | D6: External | E6: Completed | F6: Bruceshire | G6: Heather Shaffer | H6: 4 | I6: 145.99
A7: 1006 | B7: 45143 | C7: Project Management | D7: Internal | E7: Failed | F7: Erinfort | G7: Michael Duke | H7: 2 | I7: 838.07
A8: 1007 | B8: 45060 | C8: Leadership Development | D8: External | E8: Failed | F8: New Christopher | G8: Virginia Clayton DVM | H8: 2 | I8: 667.32
A9: 1008 | B9: 44965 | C9: Technical Skills | D9: External | E9: Failed | F9: Lowemouth | G9: Erica Maxwell | H9: 2 | I9: 758.18
A10: 1009 | B10: 44794 | C10: Customer Service | D10: Internal | E10: Failed | F10: Johnland | G10: Katelyn Hartman | H10: 2 | I10: 101.21
A11: 1010 | B11: 44792 | C11: Communication Skills | D11: External | E11: Failed | F11: Lake Kimfurt | G11: Rhonda Clark | H11: 5 | I11: 332.25
A12: 1011 | B12: 44723 | C12: Communication Skills | D12: Internal | E12: Completed | F12: Smithshire | G12: Natalie Fields | H12: 1 | I12: 803.98
A13: 1012 | B13: 45013 | C13: Technical Skills | D13: External | E13: Failed | F13: Howardburgh | G13: Theresa Martinez | H13: 3 | I13: 887.08
... A3001: 4000 | B3001: 44722 | C3001: Leadership Development | D3001: Internal | E3001: Completed | F3001: Jamesfurt | G3001: Michael Mckenzie | H3001: 4 | I3001: 951.27

Sheet employee_engagement survey data
A1: Employee ID | B1: Survey Date | C1: Engagement Score | D1: Satisfaction Score | E1: Work/Life Balance Score
A2: 1001 | B2: 44844 | C2: 2 | D2: 5 | E2: 5 | I2: Calculation table | J2: Column1
A3: 1002 | B3: 45141 | C3: 4 | D3: 5 | E3: 3 | I3: Engagement_Total | J3: =SUM(Table3[Engagement Score]) -> 8819
A4: 1003 | B4: 44929 | C4: 2 | D4: 5 | E4: 2 | I4: Engagement_ Average | J4: =AVERAGE(Table3[Engagement Score]) -> 2.9396667
A5: 1004 | B5: 45137 | C5: 3 | D5: 5 | E5: 3 | I5: Total_Satisfaction_Score | J5: =SUM(Table3[Satisfaction Score]) -> 9066
A6: 1005 | B6: 45096 | C6: 2 | D6: 4 | E6: 5 | I6: Average_Satisfaction_Score | J6: =AVERAGE(Table3[Satisfaction Score]) -> 3.022
A7: 1006 | B7: 45049 | C7: 5 | D7: 2 | E7: 1 | I7: Total_Work/Life Balance Score | J7: =SUM(Table3[Work/Life Balance Score]) -> 8967
A8: 1007 | B8: 45125 | C8: 2 | D8: 1 | E8: 5 | I8: Average_Work/Life_Score | J8: =AVERAGE(Table3[Work/Life Balance Score]) -> 2.989
A9: 1008 | B9: 45098 | C9: 5 | D9: 2 | E9: 2
A10: 1009 | B10: 45083 | C10: 2 | D10: 5 | E10: 1
A11: 1010 | B11: 44819 | C11: 2 | D11: 4 | E11: 2
A12: 1011 | B12: 44903 | C12: 1 | D12: 2 | E12: 3
A13: 1012 | B13: 44939 | C13: 3 | D13: 5 | E13: 4
A14: 1013 | B14: 44908 | C14: 5 | D14: 4 | E14: 3
A15: 1014 | B15: 45105 | C15: 4 | D15: 4 | E15: 1
A16: 1015 | B16: 45118 | C16: 1 | D16: 1 | E16: 3
A17: 1016 | B17: 44904 | C17: 2 | D17: 3 | E17: 2
A18: 1017 | B18: 45123 | C18: 4 | D18: 1 | E18: 3
A19: 1018 | B19: 45098 | C19: 4 | D19: 1 | E19: 4
A20: 1019 | B20: 45098 | C20: 1 | D20: 3 | E20: 5
... A3001: 4000 | B3001: 45037 | C3001: 3 | D3001: 2 | E3001: 1

Sheet recruitment_data
A1: Applicant ID | B1: Application Date | C1: Full Name | D1: Gender | E1: Date of Birth | F1: Phone | G1: Email | H1: Address | I1: City | J1: State | K1: Zip Code | L1: Country | M1: Education Level | N1: Years of Experience | O1: Desired Salary | P1: Job Title | Q1: Status
A2: 1001 | B2: 45080 | C2: Scott Sheppard | D2: Male | E2: 33847 | F2: 4214297655x39421 | G2: perezjanet@example.org | H2: 597, Smith Point | I2: Hollandfort | J2: NV | K2: 57588 | L2: Micronesia | M2: High School | N2: 8 | O2: 60103.21 | P2: Chief Technology Officer | Q2: Interviewing
A3: 1002 | B3: 45061 | C3: Stanley Lewis | D3: Male | E3: 23861 | F3: 14515745308x1681 | G3: grossmark@example.com | H3: 8116, Stuart Loop | I3: Port Margaretfurt | J3: TN | K3: 14726 | L3: Greenland | M3: Bachelor's Degree | N3: 17 | O3: 64575.84 | P3: Designer, furniture | Q3: Rejected
A4: 1003 | B4: 45142 | C4: Javier Li | D4: Female | E4: 26733 | F4: 8589015499 | G4: katiemaldonado@example.com | H4: 5940, Barr Villages Suite 075 | I4: Dianaland | J4: TX | K4: 4699 | L4: China | M4: PhD | N4: 20 | O4: 39422.71 | P4: Sound technician, broadcasting/film/video | Q4: Rejected
A5: 1004 | B5: 45135 | C5: Christopher Johnston | D5: Other | E5: 36985 | F5: 8536811839x2010 | G5: sheila73@example.com | H5: 442, Lewis Mount | I5: Youngfurt | J5: GA | K5: 34455 | L5: Ghana | M5: High School | N5: 8 | O5: 51045.11 | P5: Air cabin crew | Q5: Rejected
A6: 1005 | B6: 45082 | C6: Melissa Hicks | D6: Other | E6: 28658 | F6: 3645758478x67812 | G6: emilypatterson@example.org | H6: 95961, Taylor Circles Apt. 169 | I6: East Ashleyborough | J6: IN | K6: 21014 | L6: Solomon Islands | M6: Master's Degree | N6: 0 | O6: 52792.86 | P6: Art therapist | Q6: Interviewing
A7: 1006 | B7: 45133 | C7: Christian Maddox | D7: Female | E7: 30481 | F7: 8949402919 | G7: pvelasquez@example.net | H7: 3030, Bell Islands | I7: Boonefort | J7: NC | K7: 34763 | L7: Liberia | M7: Master's Degree | N7: 18 | O7: 97746.62 | P7: Engineer, electronics | Q7: In Review
A8: 1007 | B8: 45086 | C8: Paul Hammond | D8: Female | E8: 23239 | F8: Unknown | G8: aclayton@example.net | H8: 58473, Jenna Trail | I8: Port Barry | J8: GA | K8: 57472 | L8: Congo | M8: High School | N8: 11 | O8: 80119.39 | P8: Scientist, research (maths) | Q8: Offered
A9: 1008 | B9: 45122 | C9: Madison Williamson | D9: Male | E9: 28740 | F9: 0019029929557x692 | G9: jeffreyellis@example.com | H9: 24740, Gregory Stravenue Suite 212 | I9: New Luisfort | J9: VA | K9: 71682 | L9: Pitcairn Islands | M9: Bachelor's Degree | N9: 0 | O9: 41578.78 | P9: Teacher, primary school | Q9: Offered
A10: 1009 | B10: 45093 | C10: Rachael Duran | D10: Male | E10: 35684 | F10: 17385836354x63335 | G10: hamptontimothy@example.net | H10: 375, Flowers Well | I10: Amandashire | J10: PW | K10: 25218 | L10: Spain | M10: High School | N10: 15 | O10: 44489.6 | P10: Phytotherapist | Q10: Interviewing
A11: 1010 | B11: 45071 | C11: Sherri Taylor | D11: Male | E11: 30430 | F11: 9153720499 | G11: cshaw@example.net | H11: 037, Quinn Route | I11: Garrisonmouth | J11: CA | K11: 82074 | L11: Gabon | M11: Master's Degree | N11: 4 | O11: 97363.53 | P11: Pilot, airline | Q11: Offered
A12: 1011 | B12: 45060 | C12: Jennifer Weaver | D12: Other | E12: 36090 | F12: 8524358495 | G12: sloankrista@example.org | H12: 700, Quinn Green Suite 066 | I12: Haileyville | J12: MS | K12: 37729 | L12: Switzerland | M12: PhD | N12: 19 | O12: 39252.38 | P12: Theatre director | Q12: In Review
A13: 1012 | B13: 45081 | C13: Kyle Blake | D13: Other | E13: 36975 | F13: 0015279079332x4819 | G13: shelia63@example.net | H13: 611, Thomas Dam Suite 296 | I13: East Melinda | J13: OH | K13: 62970 | L13: China | M13: Bachelor's Degree | N13: 7 | O13: 79650.82 | P13: Corporate treasurer | Q13: Applied
... A3001: 4000 | B3001: 45114 | C3001: Charles Hernandez | D3001: Female | E3001: 29373 | F3001: 7727672580 | G3001: murrayallison@example.com | H3001: 146, Cheryl Highway | I3001: Hallland | J3001: OR | K3001: 8592 | L3001: Netherlands | M3001: Bachelor's Degree | N3001: 1 | O3001: 89853.85 | P3001: Loss adjuster, chartered | Q3001: Rejected

Sheet VLOOKUP_table
A1: EmpID | B1: Full Name | C1: StartDate | D1: ExitDate | E1: Title | F1: Supervisor | G1: ADEmail | H1: BusinessUnit | I1: EmployeeStatus | J1: EmployeeType | K1: PayZone | L1: EmployeeClassificationType | M1: TerminationType | N1: TerminationDescription | O1: DepartmentType | P1: Division | Q1: DOB | R1: State | S1: JobFunctionDescription | T1: GenderCode | U1: LocationCode | V1: RaceDesc | W1: MaritalDesc | X1: Performance Score | Y1: Current Employee Rating | Z1: Engagement Score | AA1: Satisfaction Score | AB1: Work/Life Balance Score | AC1: Training Program Name | AD1: Training Type | AE1: Training Outcome | AF1: Location | AG1: Trainer | AH1: Training Duration(Days)
A2: 1001 | B2: Susan Exantus | C2: 43706 | D2: N/A | E2: Software Engineer | F2: Angela Carlson | G2: susan.exantus@bilearner.com | H2: BPC | I2: Active | J2: Part-Time | K2: Zone A | L2: Part-Time | M2: Unk | N2: N/A | O2: Software Engineering | P2: Engineers | Q2: 21084 | R2: MA | S2: Engineer | T2: Female | U2: 1749 | V2: Black | W2: Married | X2: Fully Meets | Y2: 3 | Z2: =VLOOKUP(A2,Table3[],3,0) -> 2 | AA2: =VLOOKUP(A2,'employee_engagement survey data'!A2:E466,4,0) -> 5 | AB2: =VLOOKUP(A2,'employee_engagement survey data'!A2:E241,5,0) -> 5 | AC2: =VLOOKUP(A2,training_and_development!A2:F39,3,0) -> Customer Service | AD2: =VLOOKUP(A2,training_and_development!A2:E391,4,0) -> Internal | AE2: =VLOOKUP(A2,training_and_development!A2:F2999,5,0) -> Failed | AF2: =VLOOKUP(A2,training_and_development!A1:G21,6,0) -> Port Greg | AG2: =VLOOKUP(A2,training_and_development!A2:H10,7,0) -> Amanda Daniels | AH2: =VLOOKUP(A2,training_and_development!A2:H5,8,0) -> 4
A3: 1002 | B3: Sandra Martin | C3: 44907 | D3: 45074 | E3: Software Engineer | F3: Angela Hayes | G3: sandra.martin@bilearner.com | H3: NEL | I3: Terminated for Cause | J3: Part-Time | K3: Zone A | L3: Temporary | M3: Involuntary | N3: Behind buy our of very claim. | O3: Software Engineering | P3: Catv | Q3: 18452 | R3: MA | S3: Foreman | T3: Female | U3: 2135 | V3: Asian | W3: Widowed | X3: Fully Meets | Y3: 3 | Z3: =VLOOKUP(A3,Table3[],3,0) -> 4 | AA3: =VLOOKUP(A3,'employee_engagement survey data'!A3:E467,4,0) -> 5 | AB3: =VLOOKUP(A3,'employee_engagement survey data'!A3:E242,5,0) -> 3 | AC3: =VLOOKUP(A3,training_and_development!A3:F40,3,0) -> Leadership Development | AD3: =VLOOKUP(A3,training_and_development!A3:E392,4,0) -> Internal | AE3: =VLOOKUP(A3,training_and_development!A3:F3000,5,0) -> Failed | AF3: =VLOOKUP(A3,training_and_development!A2:G22,6,0) -> Brandonview | AG3: =VLOOKUP(A3,training_and_development!A3:H11,7,0) -> Brittany Chambers | AH3: =VLOOKUP(A3,training_and_development!A3:H6,8,0) -> 2
A4: 1003 | B4: Keyla Del Bosque | C4: 44993 | D4: 45000 | E4: Software Engineer | F4: Christina Copeland | G4: keyla.delbosque@bilearner.com | H4: WBL | I4: Voluntarily Terminated | J4: Contract | K4: Zone A | L4: Part-Time | M4: Voluntary | N4: Some make teach quite range seem conference. | O4: Software Engineering | P4: Field Operations | Q4: 26991 | R4: MA | S4: Foreman | T4: Female | U4: 2176 | V4: White | W4: Married | X4: Fully Meets | Y4: 3 | Z4: =VLOOKUP(A4,Table3[],3,0) -> 2 | AA4: =VLOOKUP(A4,'employee_engagement survey data'!A4:E468,4,0) -> 5 | AB4: =VLOOKUP(A4,'employee_engagement survey data'!A4:E243,5,0) -> 2 | AC4: =VLOOKUP(A4,training_and_development!A4:F41,3,0) -> Technical Skills | AD4: =VLOOKUP(A4,training_and_development!A4:E393,4,0) -> Internal | AE4: =VLOOKUP(A4,training_and_development!A4:F3001,5,0) -> Failed | AF4: =VLOOKUP(A4,training_and_development!A3:G23,6,0) -> Port Briannahaven | AG4: =VLOOKUP(A4,training_and_development!A4:H12,7,0) -> Mark Roberson | AH4: =VLOOKUP(A4,training_and_development!A4:H7,8,0) -> 4
A5: 1004 | B5: Andrew Szabo | C5: 43980 | D5: 44260 | E5: Software Engineer | F5: Jennifer Cohen | G5: andrew.szabo@bilearner.com | H5: PYZ | I5: Terminated for Cause | J5: Part-Time | K5: Zone C | L5: Part-Time | M5: Involuntary | N5: Enter beautiful social store. | O5: Software Engineering | P5: Project Management - Con | Q5: 20847 | R5: MA | S5: Coordinator | T5: Male | U5: 2140 | V5: Black | W5: Single | X5: Fully Meets | Y5: 3 | Z5: =VLOOKUP(A5,Table3[],3,0) -> 3 | AA5: =VLOOKUP(A5,'employee_engagement survey data'!A5:E469,4,0) -> 5 | AB5: =VLOOKUP(A5,'employee_engagement survey data'!A5:E244,5,0) -> 3 | AC5: =VLOOKUP(A5,training_and_development!A5:F42,3,0) -> Customer Service | AD5: =VLOOKUP(A5,training_and_development!A5:E394,4,0) -> Internal | AE5: =VLOOKUP(A5,training_and_development!A5:F3002,5,0) -> Completed | AF5: =VLOOKUP(A5,training_and_development!A4:G24,6,0) -> Knightborough | AG5: =VLOOKUP(A5,training_and_development!A5:H13,7,0) -> Richard Fisher | AH5: =VLOOKUP(A5,training_and_development!A5:H8,8,0) -> 2
A6: 1005 | B6: Luke Patronick | C6: 44820 | D6: N/A | E6: Software Engineer | F6: Mr. Jesus Richards | G6: colby.andreola@bilearner.com | H6: SVG | I6: Voluntarily Terminated | J6: Full-Time | K6: Zone B | L6: S | M6: Unk | N6: N/A | O6: Software Engineering | P6: Field Operations | Q6: 25777 | R6: MA | S6: Project Manager | T6: Male | U6: 1844 | V6: Black | W6: Divorced | X6: Fully Meets | Y6: 3 | Z6: =VLOOKUP(A6,Table3[],3,0) -> 2 | AA6: =VLOOKUP(A6,'employee_engagement survey data'!A6:E470,4,0) -> 4 | AB6: =VLOOKUP(A6,'employee_engagement survey data'!A6:E245,5,0) -> 5 | AC6: =VLOOKUP(A6,training_and_development!A6:F43,3,0) -> Communication Skills | AD6: =VLOOKUP(A6,training_and_development!A6:E395,4,0) -> External | AE6: =VLOOKUP(A6,training_and_development!A6:F3003,5,0) -> Completed | AF6: =VLOOKUP(A6,training_and_development!A5:G25,6,0) -> Bruceshire | AG6: =VLOOKUP(A6,training_and_development!A6:H14,7,0) -> Heather Shaffer | AH6: =VLOOKUP(A6,training_and_development!A6:H9,8,0) -> 4
A7: 1006 | B7: Colby Andreola | C7: 44423 | D7: 44520 | E7: Software Engineer | F7: Beth Johnson | G7: edward.true@bilearner.com | H7: MSC | I7: Voluntarily Terminated | J7: Full-Time | K7: Zone C | L7: Part-Time | M7: Resignation | N7: Throughout yet in serious here wish. | O7: Software Engineering | P7: Engineers | Q7: 21600 | R7: MA | S7: Administrative | T7: Female | U7: 2110 | V7: White | W7: Widowed | X7: Fully Meets | Y7: 3 | Z7: =VLOOKUP(A7,Table3[],3,0) -> 5 | AA7: =VLOOKUP(A7,'employee_engagement survey data'!A7:E471,4,0) -> 2 | AB7: =VLOOKUP(A7,'employee_engagement survey data'!A7:E246,5,0) -> 1 | AC7: =VLOOKUP(A7,training_and_development!A7:F44,3,0) -> Project Management | AD7: =VLOOKUP(A7,training_and_development!A7:E396,4,0) -> Internal | AE7: =VLOOKUP(A7,training_and_development!A7:F3004,5,0) -> Failed | AF7: =VLOOKUP(A7,training_and_development!A6:G26,6,0) -> Erinfort | AG7: =VLOOKUP(A7,training_and_development!A7:H15,7,0) -> Michael Duke | AH7: =VLOOKUP(A7,training_and_development!A7:H10,8,0) -> 2
A8: 1007 | B8: Edward TRUE | C8: 44129 | D8: 44465 | E8: Software Engineer | F8: Raymond Adams | G8: judith.carabbio@bilearner.com | H8: SVG | I8: Voluntarily Terminated | J8: Part-Time | K8: Zone A | L8: Part-Time | M8: Involuntary | N8: Recently however meeting economic. | O8: Software Engineering | P8: General - Con | Q8: 36603 | R8: MA | S8: Lineman | T8: Male | U8: 2451 | V8: Black | W8: Widowed | X8: Fully Meets | Y8: 3 | Z8: =VLOOKUP(A8,Table3[],3,0) -> 2 | AA8: =VLOOKUP(A8,'employee_engagement survey data'!A8:E472,4,0) -> 1 | AB8: =VLOOKUP(A8,'employee_engagement survey data'!A8:E247,5,0) -> 5 | AC8: =VLOOKUP(A8,training_and_development!A8:F45,3,0) -> Leadership Development | AD8: =VLOOKUP(A8,training_and_development!A8:E397,4,0) -> External | AE8: =VLOOKUP(A8,training_and_development!A8:F3005,5,0) -> Failed | AF8: =VLOOKUP(A8,training_and_development!A7:G27,6,0) -> New Christopher | AG8: =VLOOKUP(A8,training_and_development!A8:H16,7,0) -> Virginia Clayton DVM | AH8: =VLOOKUP(A8,training_and_development!A8:H11,8,0) -> 2
A9: 1008 | B9: Judith Carabbio | C9: 43705 | D9: 43955 | E9: Software Engineer | F9: Jessica Rhodes | G9: adell.saada@bilearner.com | H9: BPC | I9: Voluntarily Terminated | J9: Contract | K9: Zone B | L9: Temporary | M9: Voluntary | N9: Instead story skill financial who. | O9: Software Engineering | P9: General - Con | Q9: 29941 | R9: MA | S9: Foreman | T9: Female | U9: 2132 | V9: Hispanic | W9: Married | X9: Fully Meets | Y9: 3 | Z9: =VLOOKUP(A9,Table3[],3,0) -> 5 | AA9: =VLOOKUP(A9,'employee_engagement survey data'!A9:E473,4,0) -> 2 | AB9: =VLOOKUP(A9,'employee_engagement survey data'!A9:E248,5,0) -> 2 | AC9: =VLOOKUP(A9,training_and_development!A9:F46,3,0) -> Technical Skills | AD9: =VLOOKUP(A9,training_and_development!A9:E398,4,0) -> External | AE9: =VLOOKUP(A9,training_and_development!A9:F3006,5,0) -> Failed | AF9: =VLOOKUP(A9,training_and_development!A8:G28,6,0) -> Lowemouth | AG9: =VLOOKUP(A9,training_and_development!A9:H17,7,0) -> Erica Maxwell | AH9: =VLOOKUP(A9,training_and_development!A9:H12,8,0) -> 2
A10: 1009 | B10: Adell Saada | C10: 43629 | D10: 44938 | E10: Software Engineer | F10: Steven Tran | G10: kamari.hunter@bilearner.com | H10: NEL | I10: Terminated for Cause | J10: Part-Time | K10: Zone C | L10: Temporary | M10: Retirement | N10: Exactly vote including easy. | O10: Software Engineering | P10: General - Con | Q10: 31837 | R10: MA | S10: Model Assistant | T10: Female | U10: 2132 | V10: Other | W10: Single | X10: Fully Meets | Y10: 3 | Z10: =VLOOKUP(A10,Table3[],3,0) -> 2 | AA10: =VLOOKUP(A10,'employee_engagement survey data'!A10:E474,4,0) -> 5 | AB10: =VLOOKUP(A10,'employee_engagement survey data'!A10:E249,5,0) -> 1 | AC10: =VLOOKUP(A10,training_and_development!A10:F47,3,0) -> Customer Service | AD10: =VLOOKUP(A10,training_and_development!A10:E399,4,0) -> Internal | AE10: =VLOOKUP(A10,training_and_development!A10:F3007,5,0) -> Failed | AF10: =VLOOKUP(A10,training_and_development!A9:G29,6,0) -> Johnland | AG10: =VLOOKUP(A10,training_and_development!A10:H18,7,0) -> Katelyn Hartman | AH10: =VLOOKUP(A10,training_and_development!A10:H13,8,0) -> 2
A11: 1010 | B11: Kamari Hunter | C11: 44208 | D11: 44638 | E11: Software Engineer | F11: Kristen Collier | G11: sarah.malone@bilearner.com | H11: EW | I11: Terminated for Cause | J11: Part-Time | K11: Zone C | L11: Temporary | M11: Voluntary | N11: West note present Mr woman family. | O11: Software Engineering | P11: Field Operations | Q11: 33898 | R11: MA | S11: Supervisor | T11: Male | U11: 12889 | V11: Hispanic | W11: Divorced | X11: Fully Meets | Y11: 3 | Z11: =VLOOKUP(A11,Table3[],3,0) -> 2 | AA11: =VLOOKUP(A11,'employee_engagement survey data'!A11:E475,4,0) -> 4 | AB11: =VLOOKUP(A11,'employee_engagement survey data'!A11:E250,5,0) -> 2 | AC11: =VLOOKUP(A11,training_and_development!A11:F48,3,0) -> Communication Skills | AD11: =VLOOKUP(A11,training_and_development!A11:E400,4,0) -> External | AE11: =VLOOKUP(A11,training_and_development!A11:F3008,5,0) -> Failed | AF11: =VLOOKUP(A11,training_and_development!A10:G30,6,0) -> Lake Kimfurt | AG11: =VLOOKUP(A11,training_and_development!A11:H19,7,0) -> Rhonda Clark | AH11: =VLOOKUP(A11,training_and_development!A11:H14,8,0) -> 5
A12: 1011 | B12: Sarah Malone | C12: 44599 | D12: 44969 | E12: Software Engineer | F12: David Lopez | G12: skyler.blackwell@bilearner.com | H12: MSC | I12: Terminated for Cause | J12: Contract | K12: Zone A | L12: Temporary | M12: Resignation | N12: Professor situation they bag interest there. | O12: Software Engineering | P12: General - Con | Q12: 17585 | R12: MA | S12: Foreman | T12: Male | U12: 21340 | V12: Hispanic | W12: Married | X12: Fully Meets | Y12: 3 | Z12: =VLOOKUP(A12,Table3[],3,0) -> 1 | AA12: =VLOOKUP(A12,'employee_engagement survey data'!A12:E476,4,0) -> 2 | AB12: =VLOOKUP(A12,'employee_engagement survey data'!A12:E251,5,0) -> 3 | AC12: =VLOOKUP(A12,training_and_development!A12:F49,3,0) -> Communication Skills | AD12: =VLOOKUP(A12,training_and_development!A12:E401,4,0) -> Internal | AE12: =VLOOKUP(A12,training_and_development!A12:F3009,5,0) -> Completed | AF12: =VLOOKUP(A12,training_and_development!A11:G31,6,0) -> Smithshire | AG12: =VLOOKUP(A12,training_and_development!A12:H20,7,0) -> Natalie Fields | AH12: =VLOOKUP(A12,training_and_development!A12:H15,8,0) -> 1
A13: 1012 | B13: Skyler Blackwell | C13: 44144 | D13: 44353 | E13: Software Engineer | F13: Candice Schmidt | G13: kole.quinn@bilearner.com | H13: TNS | I13: Voluntarily Terminated | J13: Contract | K13: Zone A | L13: Temporary | M13: Involuntary | N13: Get apply economy artist right benefit ground. | O13: Software Engineering | P13: General - Eng | Q13: 28766 | R13: MA | S13: Administrative | T13: Male | U13: 67544 | V13: White | W13: Single | X13: Fully Meets | Y13: 3 | Z13: =VLOOKUP(A13,Table3[],3,0) -> 3 | AA13: =VLOOKUP(A13,'employee_engagement survey data'!A13:E477,4,0) -> 5 | AB13: =VLOOKUP(A13,'employee_engagement survey data'!A13:E252,5,0) -> 4 | AC13: =VLOOKUP(A13,training_and_development!A13:F50,3,0) -> Technical Skills | AD13: =VLOOKUP(A13,training_and_development!A13:E402,4,0) -> External | AE13: =VLOOKUP(A13,training_and_development!A13:F3010,5,0) -> Failed | AF13: =VLOOKUP(A13,training_and_development!A12:G32,6,0) -> Howardburgh | AG13: =VLOOKUP(A13,training_and_development!A13:H21,7,0) -> Theresa Martinez | AH13: =VLOOKUP(A13,training_and_development!A13:H16,8,0) -> 3
A14: 1013 | B14: Jasmin Shah | C14: 43964 | D14: N/A | E14: Software Engineer | F14: Christy Craig | G14: jayda.reese@bilearner.com | H14: PYZ | I14: Terminated for Cause | J14: Part-Time | K14: Zone B | L14: Full-Time | M14: Unk | N14: N/A | O14: Software Engineering | P14: Engineers | Q14: 27352 | R14: MA | S14: Engineer | T14: Male | U14: 36398 | V14: Asian | W14: Single | X14: Fully Meets | Y14: 3 | Z14: =VLOOKUP(A14,Table3[],3,0) -> 5 | AA14: =VLOOKUP(A14,'employee_engagement survey data'!A14:E478,4,0) -> 4 | AB14: =VLOOKUP(A14,'employee_engagement survey data'!A14:E253,5,0) -> 3 | AC14: =VLOOKUP(A14,training_and_development!A14:F51,3,0) -> Project Management | AD14: =VLOOKUP(A14,training_and_development!A14:E403,4,0) -> External | AE14: =VLOOKUP(A14,training_and_development!A14:F3011,5,0) -> Failed | AF14: =VLOOKUP(A14,training_and_development!A13:G33,6,0) -> East Jessicatown | AG14: =VLOOKUP(A14,training_and_development!A14:H22,7,0) -> Michael Marks | AH14: =VLOOKUP(A14,training_and_development!A14:H17,8,0) -> 2
A15: 1014 | B15: Kole Quinn | C15: 44926 | D15: 45120 | E15: Shared Services Manager | F15: Jermaine Weaver | G15: julien.whitehead@bilearner.com | H15: WBL | I15: Voluntarily Terminated | J15: Part-Time | K15: Zone A | L15: Full-Time | M15: Retirement | N15: I back place no three offer economic. | O15: Software Engineering | P15: Catv | Q15: 19553 | R15: MA | S15: Clerk | T15: Male | U15: 2562 | V15: Other | W15: Single | X15: Fully Meets | Y15: 3 | Z15: =VLOOKUP(A15,Table3[],3,0) -> 4 | AA15: =VLOOKUP(A15,'employee_engagement survey data'!A15:E479,4,0) -> 4 | AB15: =VLOOKUP(A15,'employee_engagement survey data'!A15:E254,5,0) -> 1 | AC15: =VLOOKUP(A15,training_and_development!A15:F52,3,0) -> Customer Service | AD15: =VLOOKUP(A15,training_and_development!A15:E404,4,0) -> External | AE15: =VLOOKUP(A15,training_and_development!A15:F3012,5,0) -> Failed | AF15: =VLOOKUP(A15,training_and_development!A14:G34,6,0) -> Watersview | AG15: =VLOOKUP(A15,training_and_development!A15:H23,7,0) -> Rachel Jones | AH15: =VLOOKUP(A15,training_and_development!A15:H18,8,0) -> 2
A16: 1015 | B16: Ansley Jackson | C16: 43437 | D16: N/A | E16: Shared Services Manager | F16: James Barajas | G16: alan.haynes@bilearner.com | H16: NEL | I16: Voluntarily Terminated | J16: Contract | K16: Zone A | L16: Part-Time | M16: Unk | N16: N/A | O16: Software Engineering | P16: People Services | Q16: 22619 | R16: MA | S16: Vp | T16: Female | U16: 22621 | V16: White | W16: Married | X16: Fully Meets | Y16: 3 | Z16: =VLOOKUP(A16,Table3[],3,0) -> 1 | AA16: =VLOOKUP(A16,'employee_engagement survey data'!A16:E480,4,0) -> 1 | AB16: =VLOOKUP(A16,'employee_engagement survey data'!A16:E255,5,0) -> 3 | AC16: =VLOOKUP(A16,training_and_development!A16:F53,3,0) -> Leadership Development | AD16: =VLOOKUP(A16,training_and_development!A16:E405,4,0) -> External | AE16: =VLOOKUP(A16,training_and_development!A16:F3013,5,0) -> Completed | AF16: =VLOOKUP(A16,training_and_development!A15:G35,6,0) -> Port Ninaland | AG16: =VLOOKUP(A16,training_and_development!A16:H24,7,0) -> Jennifer Olson | AH16: =VLOOKUP(A16,training_and_development!A16:H19,8,0) -> 1
A17: 1016 | B17: Jayda Reese | C17: 43882 | D17: 44345 | E17: Senior BI Developer | F17: Tyler Davis | G17: kamryn.herrera@bilearner.com | H17: PL | I17: Voluntarily Terminated | J17: Part-Time | K17: Zone B | L17: Part-Time | M17: Involuntary | N17: Friend agree stock teach price fish. | O17: Admin Offices | P17: Shop (Fleet) | Q17: 20522 | R17: MA | S17: Mechanic | T17: Female | U17: 64065 | V17: White | W17: Single | X17: Fully Meets | Y17: 3 | Z17: =VLOOKUP(A17,Table3[],3,0) -> 2 | AA17: =VLOOKUP(A17,'employee_engagement survey data'!A17:E481,4,0) -> 3 | AB17: =VLOOKUP(A17,'employee_engagement survey data'!A17:E256,5,0) -> 2 | AC17: =VLOOKUP(A17,training_and_development!A17:F54,3,0) -> Communication Skills | AD17: =VLOOKUP(A17,training_and_development!A17:E406,4,0) -> External | AE17: =VLOOKUP(A17,training_and_development!A17:F3014,5,0) -> Completed | AF17: =VLOOKUP(A17,training_and_development!A16:G36,6,0) -> Lake Stuartfurt | AG17: =VLOOKUP(A17,training_and_development!A17:H25,7,0) -> Eric Johnson | AH17: =VLOOKUP(A17,training_and_development!A17:H20,8,0) -> 2
A18: 1017 | B18: Julien Whitehead | C18: 44081 | D18: 44545 | E18: Senior BI Developer | F18: Joshua Gonzalez | G18: kelvin.foster@bilearner.com | H18: BPC | I18: Voluntarily Terminated | J18: Full-Time | K18: Zone B | L18: Full-Time | M18: Involuntary | N18: True system strong often experience. | O18: Admin Offices | P18: Field Operations | Q18: 17353 | R18: MA | S18: Laborer | T18: Female | U18: 97374 | V18: Black | W18: Single | X18: Fully Meets | Y18: 3 | Z18: =VLOOKUP(A18,Table3[],3,0) -> 4 | AA18: =VLOOKUP(A18,'employee_engagement survey data'!A18:E482,4,0) -> 1 | AB18: =VLOOKUP(A18,'employee_engagement survey data'!A18:E257,5,0) -> 3 | AC18: =VLOOKUP(A18,training_and_development!A18:F55,3,0) -> Technical Skills | AD18: =VLOOKUP(A18,training_and_development!A18:E407,4,0) -> External | AE18: =VLOOKUP(A18,training_and_development!A18:F3015,5,0) -> Completed | AF18: =VLOOKUP(A18,training_and_development!A17:G37,6,0) -> Cooleybury | AG18: =VLOOKUP(A18,training_and_development!A18:H26,7,0) -> Joseph Mcintyre | AH18: =VLOOKUP(A18,training_and_development!A18:H21,8,0) -> 3
A19: 1018 | B19: Alan Haynes | C19: 44001 | D19: 44538 | E19: Senior BI Developer | F19: Justin Sherman | G19: joe.fletcher@bilearner.com | H19: CCDR | I19: Voluntarily Terminated | J19: Part-Time | K19: Zone A | L19: Part-Time | M19: Involuntary | N19: When price group admit fall fly around. | O19: Admin Offices | P19: General - Con | Q19: 15396 | R19: MA | S19: Laborer | T19: Female | U19: 87646 | V19: White | W19: Married | X19: Fully Meets | Y19: 3 | Z19: =VLOOKUP(A19,Table3[],3,0) -> 4 | AA19: =VLOOKUP(A19,'employee_engagement survey data'!A19:E483,4,0) -> 1 | AB19: =VLOOKUP(A19,'employee_engagement survey data'!A19:E258,5,0) -> 4 | AC19: =VLOOKUP(A19,training_and_development!A19:F56,3,0) -> Project Management | AD19: =VLOOKUP(A19,training_and_development!A19:E408,4,0) -> Internal | AE19: =VLOOKUP(A19,training_and_development!A19:F3016,5,0) -> Failed | AF19: =VLOOKUP(A19,training_and_development!A18:G38,6,0) -> Larsonborough | AG19: =VLOOKUP(A19,training_and_development!A19:H27,7,0) -> Whitney Morgan DVM | AH19: =VLOOKUP(A19,training_and_development!A19:H22,8,0) -> 2
A20: 1019 | B20: Kamryn Herrera | C20: 44848 | D20: 45135 | E20: Software Engineer | F20: Sara Holland | G20: nickolas.davila@bilearner.com | H20: EW | I20: Voluntarily Terminated | J20: Full-Time | K20: Zone A | L20: Temporary | M20: Retirement | N20: Article tough away forward home. Night author so. | O20: Software Engineering | P20: Fielders | Q20: 28822 | R20: MA | S20: Engineer | T20: Male | U20: 77974 | V20: Hispanic | W20: Widowed | X20: Fully Meets | Y20: 3 | Z20: =VLOOKUP(A20,Table3[],3,0) -> 1 | AA20: =VLOOKUP(A20,'employee_engagement survey data'!A20:E484,4,0) -> 3 | AB20: =VLOOKUP(A20,'employee_engagement survey data'!A20:E259,5,0) -> 5 | AC20: =VLOOKUP(A20,training_and_development!A20:F57,3,0) -> Project Management | AD20: =VLOOKUP(A20,training_and_development!A20:E409,4,0) -> External | AE20: =VLOOKUP(A20,training_and_development!A20:F3017,5,0) -> Completed | AF20: =VLOOKUP(A20,training_and_development!A19:G39,6,0) -> Powellland | AG20: =VLOOKUP(A20,training_and_development!A20:H28,7,0) -> Jon Garcia | AH20: =VLOOKUP(A20,training_and_development!A20:H23,8,0) -> 5
A21: 1020 | B21: Kelvin Foster | C21: 45097 | D21: 45125 | E21: Software Engineer | F21: Shelia Graham | G21: kasey.boyer@bilearner.com | H21: MSC | I21: Terminated for Cause | J21: Contract | K21: Zone C | L21: Full-Time | M21: Resignation | N21: Man issue never strategy will maintain resource. | O21: Software Engineering | P21: Field Operations | Q21: 33227 | R21: MA | S21: Supervisor | T21: Female | U21: 42126 | V21: Black | W21: Widowed | X21: Fully Meets | Y21: 3 | Z21: =VLOOKUP(A21,Table3[],3,0) -> 2 | AA21: =VLOOKUP(A21,'employee_engagement survey data'!A21:E485,4,0) -> 1 | AB21: =VLOOKUP(A21,'employee_engagement survey data'!A21:E260,5,0) -> 2 | AC21: =VLOOKUP(A21,training_and_development!A21:F58,3,0) -> Technical Skills | AD21: =VLOOKUP(A21,training_and_development!A21:E410,4,0) -> External | AE21: =VLOOKUP(A21,training_and_development!A21:F3018,5,0) -> Completed | AF21: =VLOOKUP(A21,training_and_development!A20:G40,6,0) -> Chadport | AG21: =VLOOKUP(A21,training_and_development!A21:H29,7,0) -> Nicole Taylor | AH21: =VLOOKUP(A21,training_and_development!A21:H24,8,0) -> 4
A22: 1021 | B22: Joe Fletcher | C22: 44144 | D22: 45124 | E22: Software Engineer | F22: Amanda Hayden | G22: giovanni.jenkins@bilearner.com | H22: TNS | I22: Terminated for Cause | J22: Full-Time | K22: Zone C | L22: Full-Time | M22: Resignation | N22: Section hospital clearly season history. | O22: Software Engineering | P22: General - Eng | Q22: 32533 | R22: MA | S22: Billing | T22: Male | U22: 51613 | V22: Hispanic | W22: Single | X22: Fully Meets | Y22: 3 | Z22: =VLOOKUP(A22,Table3[],3,0) -> 5 | AA22: =VLOOKUP(A22,'employee_engagement survey data'!A22:E486,4,0) -> 1 | AB22: =VLOOKUP(A22,'employee_engagement survey data'!A22:E261,5,0) -> 4 | AC22: =VLOOKUP(A22,training_and_development!A22:F59,3,0) -> Technical Skills | AD22: =VLOOKUP(A22,training_and_development!A22:E411,4,0) -> Internal | AE22: =VLOOKUP(A22,training_and_development!A22:F3019,5,0) -> Failed | AF22: =VLOOKUP(A22,training_and_development!A21:G41,6,0) -> Patrickhaven | AG22: =VLOOKUP(A22,training_and_development!A22:H30,7,0) -> Crystal Nelson | AH22: =VLOOKUP(A22,training_and_development!A22:H25,8,0) -> 1
A23: 1022 | B23: Frederick Howe | C23: 44823 | D23: N/A | E23: Software Engineer | F23: Nicole Haynes | G23: alexis.moss@bilearner.com | H23: PYZ | I23: Voluntarily Terminated | J23: Part-Time | K23: Zone A | L23: Temporary | M23: Unk | N23: N/A | O23: Software Engineering | P23: Field Operations | Q23: 22808 | R23: MA | S23: Engineer | T23: Male | U23: 12765 | V23: Black | W23: Divorced | X23: Fully Meets | Y23: 3 | Z23: =VLOOKUP(A23,Table3[],3,0) -> 1 | AA23: =VLOOKUP(A23,'employee_engagement survey data'!A23:E487,4,0) -> 4 | AB23: =VLOOKUP(A23,'employee_engagement survey data'!A23:E262,5,0) -> 4 | AC23: =VLOOKUP(A23,training_and_development!A23:F60,3,0) -> Project Management | AD23: =VLOOKUP(A23,training_and_development!A23:E412,4,0) -> Internal | AE23: =VLOOKUP(A23,training_and_development!A23:F3020,5,0) -> Failed | AF23: =VLOOKUP(A23,training_and_development!A22:G42,6,0) -> Lindseyburgh | AG23: =VLOOKUP(A23,training_and_development!A23:H31,7,0) -> Kevin Nichols | AH23: =VLOOKUP(A23,training_and_development!A23:H26,8,0) -> 1
A24: 1023 | B24: Nickolas Davila | C24: 43413 | D24: 44479 | E24: Shared Services Manager | F24: Debra Morales | G24: joanna.murphy@bilearner.com | H24: WBL | I24: Voluntarily Terminated | J24: Contract | K24: Zone C | L24: Part-Time | M24: Voluntary | N24: Each wish foot person morning per significant. | O24: Software Engineering | P24: General - Con | Q24: 33699 | R24: MA | S24: Clerk | T24: Male | U24: 64122 | V24: Hispanic | W24: Divorced | X24: Fully Meets | Y24: 3 | Z24: =VLOOKUP(A24,Table3[],3,0) -> 4 | AA24: =VLOOKUP(A24,'employee_engagement survey data'!A24:E488,4,0) -> 4 | AB24: =VLOOKUP(A24,'employee_engagement survey data'!A24:E263,5,0) -> 3 | AC24: =VLOOKUP(A24,training_and_development!A24:F61,3,0) -> Project Management | AD24: =VLOOKUP(A24,training_and_development!A24:E413,4,0) -> Internal | AE24: =VLOOKUP(A24,training_and_development!A24:F3021,5,0) -> Failed | AF24: =VLOOKUP(A24,training_and_development!A23:G43,6,0) -> West Justinborough | AG24: =VLOOKUP(A24,training_and_development!A24:H32,7,0) -> Angela Good | AH24: =VLOOKUP(A24,training_and_development!A24:H27,8,0) -> 4
A25: 1024 | B25: Kasey Boyer | C25: 43464 | D25: 44370 | E25: Shared Services Manager | F25: Chad Andrews | G25: joseph.schmidt@bilearner.com | H25: NEL | I25: Voluntarily Terminated | J25: Contract | K25: Zone A | L25: Part-Time | M25: Involuntary | N25: Free may every real agency as blue maintain. | O25: Software Engineering | P25: Fielders | Q25: 31866 | R25: MA | S25: Coordinator | T25: Female | U25: 91332 | V25: Other | W25: Divorced | X25: Fully Meets | Y25: 3 | Z25: =VLOOKUP(A25,Table3[],3,0) -> 5 | AA25: =VLOOKUP(A25,'employee_engagement survey data'!A25:E489,4,0) -> 3 | AB25: =VLOOKUP(A25,'employee_engagement survey data'!A25:E264,5,0) -> 1 | AC25: =VLOOKUP(A25,training_and_development!A25:F62,3,0) -> Project Management | AD25: =VLOOKUP(A25,training_and_development!A25:E414,4,0) -> External | AE25: =VLOOKUP(A25,training_and_development!A25:F3022,5,0) -> Completed | AF25: =VLOOKUP(A25,training_and_development!A24:G44,6,0) -> Hullmouth | AG25: =VLOOKUP(A25,training_and_development!A25:H33,7,0) -> Keith Curtis | AH25: =VLOOKUP(A25,training_and_development!A25:H28,8,0) -> 5
A26: 1025 | B26: Giovanni Jenkins | C26: 45057 | D26: 45061 | E26: Senior BI Developer | F26: John Wallace | G26: kiley.haynes@bilearner.com | H26: PL | I26: Voluntarily Terminated | J26: Full-Time | K26: Zone A | L26: Temporary | M26: Retirement | N26: Quite none ten order. | O26: Admin Offices | P26: Field Operations | Q26: 22233 | R26: MA | S26: Foreman | T26: Female | U26: 39827 | V26: Other | W26: Divorced | X26: Fully Meets | Y26: 3 | Z26: =VLOOKUP(A26,Table3[],3,0) -> 4 | AA26: =VLOOKUP(A26,'employee_engagement survey data'!A26:E490,4,0) -> 1 | AB26: =VLOOKUP(A26,'employee_engagement survey data'!A26:E265,5,0) -> 4 | AC26: =VLOOKUP(A26,training_and_development!A26:F63,3,0) -> Project Management | AD26: =VLOOKUP(A26,training_and_development!A26:E415,4,0) -> Internal | AE26: =VLOOKUP(A26,training_and_development!A26:F3023,5,0) -> Failed | AF26: =VLOOKUP(A26,training_and_development!A25:G45,6,0) -> Thompsonbury | AG26: =VLOOKUP(A26,training_and_development!A26:H34,7,0) -> Nina Rodriguez | AH26: =VLOOKUP(A26,training_and_development!A26:H29,8,0) -> 5
A27: 1026 | B27: Alexis Moss | C27: 44868 | D27: 44966 | E27: Senior BI Developer | F27: Benjamin Frederick | G27: kody.jimenez@bilearner.com | H27: BPC | I27: Voluntarily Terminated | J27: Contract | K27: Zone A | L27: Part-Time | M27: Resignation | N27: Where forward evening huge cost share eat. | O27: Admin Offices | P27: Engineers | Q27: 18574 | R27: MA | S27: Engineer | T27: Female | U27: 27418 | V27: Other | W27: Widowed | X27: Fully Meets | Y27: 3 | Z27: =VLOOKUP(A27,Table3[],3,0) -> 5 | AA27: =VLOOKUP(A27,'employee_engagement survey data'!A27:E491,4,0) -> 2 | AB27: =VLOOKUP(A27,'employee_engagement survey data'!A27:E266,5,0) -> 5 | AC27: =VLOOKUP(A27,training_and_development!A27:F64,3,0) -> Communication Skills | AD27: =VLOOKUP(A27,training_and_development!A27:E416,4,0) -> External | AE27: =VLOOKUP(A27,training_and_development!A27:F3024,5,0) -> Failed | AF27: =VLOOKUP(A27,training_and_development!A26:G46,6,0) -> Cynthiachester | AG27: =VLOOKUP(A27,training_and_development!A27:H35,7,0) -> Jennifer Robinson | AH27: =VLOOKUP(A27,training_and_development!A27:H30,8,0) -> 4
A28: 1027 | B28: Joanna Murphy | C28: 43996 | D28: 44345 | E28: Senior BI Developer | F28: Michael Ramos | G28: zoe.colon@bilearner.com | H28: CCDR | I28: Voluntarily Terminated | J28: Part-Time | K28: Zone A | L28: Full-Time | M28: Voluntary | N28: Open test message part risk. | O28: Admin Offices | P28: General - Con | Q28: 23001 | R28: MA | S28: Flagger | T28: Male | U28: 24931 | V28: Other | W28: Single | X28: Fully Meets | Y28: 3 | Z28: =VLOOKUP(A28,Table3[],3,0) -> 2 | AA28: =VLOOKUP(A28,'employee_engagement survey data'!A28:E492,4,0) -> 3 | AB28: =VLOOKUP(A28,'employee_engagement survey data'!A28:E267,5,0) -> 5 | AC28: =VLOOKUP(A28,training_and_development!A28:F65,3,0) -> Communication Skills | AD28: =VLOOKUP(A28,training_and_development!A28:E417,4,0) -> External | AE28: =VLOOKUP(A28,training_and_development!A28:F3025,5,0) -> Failed | AF28: =VLOOKUP(A28,training_and_development!A27:G47,6,0) -> East Jackstad | AG28: =VLOOKUP(A28,training_and_development!A28:H36,7,0) -> Mr. Robert Byrd MD | AH28: =VLOOKUP(A28,training_and_development!A28:H31,8,0) -> 4
A29: 1028 | B29: Joseph Schmidt | C29: 43753 | D29: 44927 | E29: Software Engineer | F29: Donna Boone | G29: nolan.perez@bilearner.com | H29: PYZ | I29: Voluntarily Terminated | J29: Full-Time | K29: Zone C | L29: Part-Time | M29: Resignation | N29: Federal less every character section think white. | O29: Software Engineering | P29: General - Con | Q29: 36821 | R29: MA | S29: Model Assistant | T29: Male | U29: 2121 | V29: Asian | W29: Single | X29: Fully Meets | Y29: 3 | Z29: =VLOOKUP(A29,Table3[],3,0) -> 5 | AA29: =VLOOKUP(A29,'employee_engagement survey data'!A29:E493,4,0) -> 5 | AB29: =VLOOKUP(A29,'employee_engagement survey data'!A29:E268,5,0) -> 4 | AC29: =VLOOKUP(A29,training_and_development!A29:F66,3,0) -> Technical Skills | AD29: =VLOOKUP(A29,training_and_development!A29:E418,4,0) -> Internal | AE29: =VLOOKUP(A29,training_and_development!A29:F3026,5,0) -> Failed | AF29: =VLOOKUP(A29,training_and_development!A28:G48,6,0) -> East Christopher | AG29: =VLOOKUP(A29,training_and_development!A29:H37,7,0) -> Gina Moore | AH29: =VLOOKUP(A29,training_and_development!A29:H32,8,0) -> 3
A30: 1029 | B30: Brittany Hurley | C30: 43949 | D30: N/A | E30: Software Engineer | F30: Jeffrey Johnston | G30: katrina.farrell@bilearner.com | H30: SVG | I30: Voluntarily Terminated | J30: Part-Time | K30: Zone B | L30: Part-Time | M30: Unk | N30: N/A | O30: Software Engineering | P30: Field Operations | Q30: 29007 | R30: MA | S30: Specialist | T30: Female | U30: 97697 | V30: Asian | W30: Divorced | X30: Fully Meets | Y30: 3 | Z30: =VLOOKUP(A30,Table3[],3,0) -> 3 | AA30: =VLOOKUP(A30,'employee_engagement survey data'!A30:E494,4,0) -> 5 | AB30: =VLOOKUP(A30,'employee_engagement survey data'!A30:E269,5,0) -> 4 | AC30: =VLOOKUP(A30,training_and_development!A30:F67,3,0) -> Project Management | AD30: =VLOOKUP(A30,training_and_development!A30:E419,4,0) -> Internal | AE30: =VLOOKUP(A30,training_and_development!A30:F3027,5,0) -> Failed | AF30: =VLOOKUP(A30,training_and_development!A29:G49,6,0) -> Lake Anthonyton | AG30: =VLOOKUP(A30,training_and_development!A30:H38,7,0) -> Christopher Rowland | AH30: =VLOOKUP(A30,training_and_development!A30:H33,8,0) -> 5
A31: 1030 | B31: Niko Hamilton | C31: 43767 | D31: N/A | E31: Software Engineer | F31: Sarah King | G31: camden.kelly@bilearner.com | H31: TNS | I31: Voluntarily Terminated | J31: Contract | K31: Zone C | L31: Temporary | M31: Unk | N31: N/A | O31: Software Engineering | P31: Field Operations | Q31: 20276 | R31: MA | S31: Foreman | T31: Male | U31: 75783 | V31: Black | W31: Single | X31: Fully Meets | Y31: 3 | Z31: =VLOOKUP(A31,Table3[],3,0) -> 4 | AA31: =VLOOKUP(A31,'employee_engagement survey data'!A31:E495,4,0) -> 4 | AB31: =VLOOKUP(A31,'employee_engagement survey data'!A31:E270,5,0) -> 1 | AC31: =VLOOKUP(A31,training_and_development!A31:F68,3,0) -> Communication Skills | AD31: =VLOOKUP(A31,training_and_development!A31:E420,4,0) -> Internal | AE31: =VLOOKUP(A31,training_and_development!A31:F3028,5,0) -> Completed | AF31: =VLOOKUP(A31,training_and_development!A30:G50,6,0) -> Longton | AG31: =VLOOKUP(A31,training_and_development!A31:H39,7,0) -> Wendy Gibson | AH31: =VLOOKUP(A31,training_and_development!A31:H34,8,0) -> 1
A32: 1031 | B32: Ruben Martinez | C32: 44314 | D32: N/A | E32: Software Engineer | F32: Cynthia Delgado | G32: kale.lang@bilearner.com | H32: WBL | I32: Voluntarily Terminated | J32: Part-Time | K32: Zone B | L32: Temporary | M32: Unk | N32: N/A | O32: Software Engineering | P32: General - Con | Q32: 26601 | R32: MA | S32: Lineman | T32: Male | U32: 26111 | V32: White | W32: Widowed | X32: Fully Meets | Y32: 3 | Z32: =VLOOKUP(A32,Table3[],3,0) -> 5 | AA32: =VLOOKUP(A32,'employee_engagement survey data'!A32:E496,4,0) -> 3 | AB32: =VLOOKUP(A32,'employee_engagement survey data'!A32:E271,5,0) -> 2 | AC32: =VLOOKUP(A32,training_and_development!A32:F69,3,0) -> Communication Skills | AD32: =VLOOKUP(A32,training_and_development!A32:E421,4,0) -> Internal | AE32: =VLOOKUP(A32,training_and_development!A32:F3029,5,0) -> Failed | AF32: =VLOOKUP(A32,training_and_development!A31:G51,6,0) -> New Williamland | AG32: =VLOOKUP(A32,training_and_development!A32:H40,7,0) -> Ashley Gonzalez | AH32: =VLOOKUP(A32,training_and_development!A32:H35,8,0) -> 1
